Workbook

Sheet Data
A1: fylkesnr | B1: fylkesnavn | C1: komm | D1: kommunenavn | E1: km_kurve | F1: rangeringKmKurve | G1: arealLand | H1: befolkning | I1: kmPerKm2 | J1: rangeringKmPerAreal | K1: MeterPerPerson | L1: rangeringMeterPerPerson | M1: løst_nettverk | N1: km_kurve_post | O1: endring% | P1: Ber_tidbruk_minutter | Q1: Timer | R1: Dagsverk | S1: Årsverk
A2: 56 | B2: Finnmark | C2: 301 | D2: Oslo | E2: 1727.18 | F2: 32.32 | G2: 426 | H2: 724290 | I2: 4.05 | J2: 4 | K2: 2 | L2: 357 | O2: =IF(N2>0,ROUND((N2-E2)/E2*100,1),"") | P2: =ROUND((E2*Tidbruk!$J$1)+(G2*Tidbruk!$J$2),0) -> 1838 | Q2: =ROUNDUP(P2/60,0) -> 31 | R2: =ROUNDUP(Q2/7.5,0) -> 5 | S2: =Q2/1690 -> 0.018343195
A3: 50 | B3: Trøndelag | C3: 1101 | D3: Eigersund | E3: 748.33 | F3: 194 | G3: 387 | H3: 15375 | I3: 1.93 | J3: 133 | K3: 49 | L3: 274 | O3: =IF(N3>0,ROUND((N3-E3)/E3*100,1),"") | P3: =ROUND((E3*Tidbruk!$J$1)+(G3*Tidbruk!$J$2),0) -> 928 | Q3: =ROUNDUP(P3/60,0) -> 16 | R3: =ROUNDUP(Q3/7.5,0) -> 3 | S3: =Q3/1690 -> 0.0094674556
A4: 33 | B4: Buskerud | C4: 1103 | D4: Stavanger | E4: 876.87 | F4: 173 | G4: 256 | H4: 150123 | I4: 3.43 | J4: 27 | K4: 6 | L4: 352 | O4: =IF(N4>0,ROUND((N4-E4)/E4*100,1),"") | P4: =ROUND((E4*Tidbruk!$J$1)+(G4*Tidbruk!$J$2),0) -> 959 | Q4: =ROUNDUP(P4/60,0) -> 16 | R4: =ROUNDUP(Q4/7.5,0) -> 3 | S4: =Q4/1690 -> 0.0094674556
A5: 34 | B5: Innlandet | C5: 1106 | D5: Haugesund | E5: 137.88 | F5: 343 | G5: 68 | H5: 38441 | I5: 2.03 | J5: 121 | K5: 4 | L5: 355 | O5: =IF(N5>0,ROUND((N5-E5)/E5*100,1),"") | P5: =ROUND((E5*Tidbruk!$J$1)+(G5*Tidbruk!$J$2),0) -> 169 | Q5: =ROUNDUP(P5/60,0) -> 3 | R5: =ROUNDUP(Q5/7.5,0) -> 1 | S5: =Q5/1690 -> 0.0017751479
A6: 34 | B6: Innlandet | C6: 1108 | D6: Sandnes | E6: 1690.13 | F6: 54 | G6: 943 | H6: 84908 | I6: 1.79 | J6: 145 | K6: 20 | L6: 323 | O6: =IF(N6>0,ROUND((N6-E6)/E6*100,1),"") | P6: =ROUND((E6*Tidbruk!$J$1)+(G6*Tidbruk!$J$2),0) -> 2141 | Q6: =ROUNDUP(P6/60,0) -> 36 | R6: =ROUNDUP(Q6/7.5,0) -> 5 | S6: =Q6/1690 -> 0.021301775
A7: 42 | B7: Agder | C7: 1111 | D7: Sokndal | E7: 229.21 | F7: 317 | G7: 267 | H7: 3371 | I7: 0.86 | J7: 273 | K7: 68 | L7: 253 | O7: =IF(N7>0,ROUND((N7-E7)/E7*100,1),"") | P7: =ROUND((E7*Tidbruk!$J$1)+(G7*Tidbruk!$J$2),0) -> 381 | Q7: =ROUNDUP(P7/60,0) -> 7 | R7: =ROUNDUP(Q7/7.5,0) -> 1 | S7: =Q7/1690 -> 0.0041420118
A8: 34 | B8: Innlandet | C8: 1112 | D8: Lund | E8: 429.15 | F8: 275 | G8: 354 | H8: 3259 | I8: 1.21 | J8: 219 | K8: 132 | L8: 180 | O8: =IF(N8>0,ROUND((N8-E8)/E8*100,1),"") | P8: =ROUND((E8*Tidbruk!$J$1)+(G8*Tidbruk!$J$2),0) -> 618 | Q8: =ROUNDUP(P8/60,0) -> 11 | R8: =ROUNDUP(Q8/7.5,0) -> 2 | S8: =Q8/1690 -> 0.0065088757
A9: 33 | B9: Buskerud | C9: 1114 | D9: Bjerkreim | E9: 1016.71 | F9: 145 | G9: 577 | H9: 2905 | I9: 1.76 | J9: 147 | K9: 350 | L9: 89 | O9: =IF(N9>0,ROUND((N9-E9)/E9*100,1),"") | P9: =ROUND((E9*Tidbruk!$J$1)+(G9*Tidbruk!$J$2),0) -> 1294 | Q9: =ROUNDUP(P9/60,0) -> 22 | R9: =ROUNDUP(Q9/7.5,0) -> 3 | S9: =Q9/1690 -> 0.013017751
A10: 46 | B10: Vestland | C10: 1119 | D10: Hå | E10: 786.17 | F10: 191 | G10: 248 | H10: 20067 | I10: 3.17 | J10: 36 | K10: 39 | L10: 294 | O10: =IF(N10>0,ROUND((N10-E10)/E10*100,1),"") | P10: =ROUND((E10*Tidbruk!$J$1)+(G10*Tidbruk!$J$2),0) -> 872 | Q10: =ROUNDUP(P10/60,0) -> 15 | R10: =ROUNDUP(Q10/7.5,0) -> 2 | S10: =Q10/1690 -> 0.0088757396
A11: 50 | B11: Trøndelag | C11: 1120 | D11: Klepp | E11: 269.39 | F11: 306 | G11: 102 | H11: 21186 | I11: 2.64 | J11: 68 | K11: 13 | L11: 335 | M11: 576.92882 | N11: 2280.1712 | O11: =IF(N11>0,ROUND((N11-E11)/E11*100,1),"") -> 746.4 | P11: =ROUND((E11*Tidbruk!$J$1)+(G11*Tidbruk!$J$2),0) -> 310 | Q11: =ROUNDUP(P11/60,0) -> 6 | R11: =ROUNDUP(Q11/7.5,0) -> 1 | S11: =Q11/1690 -> 0.0035502959
A12: 56 | B12: Finnmark | C12: 1121 | D12: Time | E12: 692.5 | F12: 205 | G12: 171 | H12: 20157 | I12: 4.05 | J12: 4 | K12: 34 | L12: 301 | O12: =IF(N12>0,ROUND((N12-E12)/E12*100,1),"") | P12: =ROUND((E12*Tidbruk!$J$1)+(G12*Tidbruk!$J$2),0) -> 737 | Q12: =ROUNDUP(P12/60,0) -> 13 | R12: =ROUNDUP(Q12/7.5,0) -> 2 | S12: =Q12/1690 -> 0.0076923077
A13: 46 | B13: Vestland | C13: 1122 | D13: Gjesdal | E13: 904.7 | F13: 171 | G13: 558 | H13: 12536 | I13: 1.62 | J13: 161 | K13: 72 | L13: 246 | O13: =IF(N13>0,ROUND((N13-E13)/E13*100,1),"") | P13: =ROUND((E13*Tidbruk!$J$1)+(G13*Tidbruk!$J$2),0) -> 1181 | Q13: =ROUNDUP(P13/60,0) -> 20 | R13: =ROUNDUP(Q13/7.5,0) -> 3 | S13: =Q13/1690 -> 0.01183432
A14: 34 | B14: Innlandet | C14: 1124 | D14: Sola | E14: 196.46 | F14: 334 | G14: 69 | H14: 29153 | I14: 2.85 | J14: 52 | K14: 7 | L14: 348 | O14: =IF(N14>0,ROUND((N14-E14)/E14*100,1),"") | P14: =ROUND((E14*Tidbruk!$J$1)+(G14*Tidbruk!$J$2),0) -> 222 | Q14: =ROUNDUP(P14/60,0) -> 4 | R14: =ROUNDUP(Q14/7.5,0) -> 1 | S14: =Q14/1690 -> 0.0023668639
A15: 46 | B15: Vestland | C15: 1127 | D15: Randaberg | E15: 82.1 | F15: 351 | G15: 24 | H15: 11795 | I15: 3.42 | J15: 28 | K15: 7 | L15: 348 | O15: =IF(N15>0,ROUND((N15-E15)/E15*100,1),"") | P15: =ROUND((E15*Tidbruk!$J$1)+(G15*Tidbruk!$J$2),0) -> 90 | Q15: =ROUNDUP(P15/60,0) -> 2 | R15: =ROUNDUP(Q15/7.5,0) -> 1 | S15: =Q15/1690 -> 0.001183432
A16: 40 | B16: Telemark | C16: 1130 | D16: Strand | E16: 658.74 | F16: 218 | G16: 235 | H16: 13813 | I16: 2.8 | J16: 54 | K16: 48 | L16: 276 | O16: =IF(N16>0,ROUND((N16-E16)/E16*100,1),"") | P16: =ROUND((E16*Tidbruk!$J$1)+(G16*Tidbruk!$J$2),0) -> 748 | Q16: =ROUNDUP(P16/60,0) -> 13 | R16: =ROUNDUP(Q16/7.5,0) -> 2 | S16: =Q16/1690 -> 0.0076923077
A17: 33 | B17: Buskerud | C17: 1133 | D17: Hjelmeland | E17: 1018.14 | F17: 144 | G17: 948 | H17: 2681 | I17: 1.07 | J17: 236 | K17: 380 | L17: 72 | O17: =IF(N17>0,ROUND((N17-E17)/E17*100,1),"") | P17: =ROUND((E17*Tidbruk!$J$1)+(G17*Tidbruk!$J$2),0) -> 1537 | Q17: =ROUNDUP(P17/60,0) -> 26 | R17: =ROUNDUP(Q17/7.5,0) -> 4 | S17: =Q17/1690 -> 0.015384615
A18: 50 | B18: Trøndelag | C18: 1134 | D18: Suldal | E18: 1420.06 | F18: 73 | G18: 1582 | H18: 3939 | I18: 0.9 | J18: 0.32 | K18: 361 | L18: 81 | O18: =IF(N18>0,ROUND((N18-E18)/E18*100,1),"") | P18: =ROUND((E18*Tidbruk!$J$1)+(G18*Tidbruk!$J$2),0) -> 2313 | Q18: =ROUNDUP(P18/60,0) -> 39 | R18: =ROUNDUP(Q18/7.5,0) -> 6 | S18: =Q18/1690 -> 0.023076923
A19: 56 | B19: Finnmark | C19: 1135 | D19: Sauda | E19: 439.95 | F19: 271 | G19: 508 | H19: 4600 | I19: 0.87 | J19: 271 | K19: 96 | L19: 218 | O19: =IF(N19>0,ROUND((N19-E19)/E19*100,1),"") | P19: =ROUND((E19*Tidbruk!$J$1)+(G19*Tidbruk!$J$2),0) -> 728 | Q19: =ROUNDUP(P19/60,0) -> 13 | R19: =ROUNDUP(Q19/7.5,0) -> 2 | S19: =Q19/1690 -> 0.0076923077
A20: 55 | B20: Troms | C20: 1144 | D20: Kvitsøy | E20: 16.53 | F20: 355 | G20: 6 | H20: 570 | I20: 2.76 | J20: 57 | K20: 29 | L20: 305 | O20: =IF(N20>0,ROUND((N20-E20)/E20*100,1),"") | P20: =ROUND((E20*Tidbruk!$J$1)+(G20*Tidbruk!$J$2),0) -> 19 | Q20: =ROUNDUP(P20/60,0) -> 1 | R20: =ROUNDUP(Q20/7.5,0) -> 1 | S20: =Q20/1690 -> 0.00059171598
A21: 55 | B21: Troms | C21: 1145 | D21: Bokn | E21: 104.28 | F21: 348 | G21: 45 | H21: 893 | I21: 2.32 | J21: 91 | K21: 117 | L21: 198 | O21: =IF(N21>0,ROUND((N21-E21)/E21*100,1),"") | P21: =ROUND((E21*Tidbruk!$J$1)+(G21*Tidbruk!$J$2),0) -> 124 | Q21: =ROUNDUP(P21/60,0) -> 3 | R21: =ROUNDUP(Q21/7.5,0) -> 1 | S21: =Q21/1690 -> 0.0017751479
A22: 56 | B22: Finnmark | C22: 1146 | D22: Tysvær | E22: 902.17 | F22: 172 | G22: 400 | H22: 11715 | I22: 2.26 | J22: 99 | K22: 77 | L22: 238 | O22: =IF(N22>0,ROUND((N22-E22)/E22*100,1),"") | P22: =ROUND((E22*Tidbruk!$J$1)+(G22*Tidbruk!$J$2),0) -> 1076 | Q22: =ROUNDUP(P22/60,0) -> 18 | R22: =ROUNDUP(Q22/7.5,0) -> 3 | S22: =Q22/1690 -> 0.010650888
A23: 40 | B23: Telemark | C23: 1149 | D23: Karmøy | E23: 636.48 | F23: 227 | G23: 219 | H23: 43723 | I23: 2.91 | J23: 48 | K23: 15 | L23: 331 | O23: =IF(N23>0,ROUND((N23-E23)/E23*100,1),"") | P23: =ROUND((E23*Tidbruk!$J$1)+(G23*Tidbruk!$J$2),0) -> 718 | Q23: =ROUNDUP(P23/60,0) -> 12 | R23: =ROUNDUP(Q23/7.5,0) -> 2 | S23: =Q23/1690 -> 0.0071005917
... A59: 34 | B59: Innlandet | C59: 1816 | D59: Vevelstad | E59: 207.35 | F59: 327 | G59: 516 | H59: 470 | I59: 0.4 | J59: 342 | K59: 441 | L59: 62 | O59: =IF(N59>0,ROUND((N59-E59)/E59*100,1),"") | P59: =ROUND((E59*Tidbruk!$J$1)+(G59*Tidbruk!$J$2),0) -> 523 | Q59: =ROUNDUP(P59/60,0) -> 9 | R59: =ROUNDUP(Q59/7.5,0) -> 2 | S59: =Q59/1690 -> 0.0053254438
A60: 50 | B60: Trøndelag | C60: 1818 | D60: Herøy | E60: 88.32 | F60: 350 | G60: 64 | H60: 1888 | I60: 1.38 | J60: 194 | K60: 47 | L60: 279 | M60: 366 | N60: 1491 | O60: =IF(N60>0,ROUND((N60-E60)/E60*100,1),"") -> 1588.2 | P60: =ROUND((E60*Tidbruk!$J$1)+(G60*Tidbruk!$J$2),0) -> 121 | Q60: =ROUNDUP(P60/60,0) -> 3 | R60: =ROUNDUP(Q60/7.5,0) -> 1 | S60: =Q60/1690 -> 0.0017751479
A61: 50 | B61: Trøndelag | C61: 1820 | D61: Alstahaug | E61: 315.32 | F61: 297 | G61: 187 | H61: 7465 | I61: 1.69 | J61: 156 | K61: 42 | L61: 289 | O61: =IF(N61>0,ROUND((N61-E61)/E61*100,1),"") | P61: =ROUND((E61*Tidbruk!$J$1)+(G61*Tidbruk!$J$2),0) -> 407 | Q61: =ROUNDUP(P61/60,0) -> 7 | R61: =ROUNDUP(Q61/7.5,0) -> 1 | S61: =Q61/1690 -> 0.0041420118
A62: 31 | B62: Østfold | C62: 1822 | D62: Leirfjord | E62: 297.78 | F62: 300 | G62: 451 | H62: 2354 | I62: 0.66 | J62: 304 | K62: 126 | L62: 188 | O62: =IF(N62>0,ROUND((N62-E62)/E62*100,1),"") | P62: =ROUND((E62*Tidbruk!$J$1)+(G62*Tidbruk!$J$2),0) -> 563 | Q62: =ROUNDUP(P62/60,0) -> 10 | R62: =ROUNDUP(Q62/7.5,0) -> 2 | S62: =Q62/1690 -> 0.0059171598
A63: 40 | B63: Telemark | C63: 1824 | D63: Vefsn | E63: 1183.48 | F63: 105 | G63: 1838 | H63: 13475 | I63: 0.64 | J63: 308 | K63: 88 | L63: 231 | O63: =IF(N63>0,ROUND((N63-E63)/E63*100,1),"") | P63: =ROUND((E63*Tidbruk!$J$1)+(G63*Tidbruk!$J$2),0) -> 2266 | Q63: =ROUNDUP(P63/60,0) -> 38 | R63: =ROUNDUP(Q63/7.5,0) -> 6 | S63: =Q63/1690 -> 0.022485207
A64: 56 | B64: Finnmark | C64: 1825 | D64: Grane | E64: 666.52 | F64: 216 | G64: 1881 | H64: 1430 | I64: 0.35 | J64: 345 | K64: 466 | L64: 57 | O64: =IF(N64>0,ROUND((N64-E64)/E64*100,1),"") | P64: =ROUND((E64*Tidbruk!$J$1)+(G64*Tidbruk!$J$2),0) -> 1827 | Q64: =ROUNDUP(P64/60,0) -> 31 | R64: =ROUNDUP(Q64/7.5,0) -> 5 | S64: =Q64/1690 -> 0.018343195
A65: 15 | B65: Møre og Romsdal | C65: 1826 | D65: Aarborte - Hattfjelldal | E65: 854.25 | F65: 179 | G65: 2411 | H65: 1274 | I65: 0.35 | J65: 345 | K65: 671 | L65: 25 | O65: =IF(N65>0,ROUND((N65-E65)/E65*100,1),"") | P65: =ROUND((E65*Tidbruk!$J$1)+(G65*Tidbruk!$J$2),0) -> 2341 | Q65: =ROUNDUP(P65/60,0) -> 40 | R65: =ROUNDUP(Q65/7.5,0) -> 6 | S65: =Q65/1690 -> 0.023668639
A66: 55 | B66: Troms | C66: 1827 | D66: Dønna | E66: 175.89 | F66: 340 | G66: 186 | H66: 1447 | I66: 0.95 | J66: 260 | K66: 122 | L66: 192 | O66: =IF(N66>0,ROUND((N66-E66)/E66*100,1),"") | P66: =ROUND((E66*Tidbruk!$J$1)+(G66*Tidbruk!$J$2),0) -> 280 | Q66: =ROUNDUP(P66/60,0) -> 5 | R66: =ROUNDUP(Q66/7.5,0) -> 1 | S66: =Q66/1690 -> 0.0029585799
A67: 34 | B67: Innlandet | C67: 1828 | D67: Nesna | E67: 207.19 | F67: 329 | G67: 181 | H67: 1770 | I67: 1.14 | J67: 225 | K67: 117 | L67: 198 | O67: =IF(N67>0,ROUND((N67-E67)/E67*100,1),"") | P67: =ROUND((E67*Tidbruk!$J$1)+(G67*Tidbruk!$J$2),0) -> 305 | Q67: =ROUNDUP(P67/60,0) -> 6 | R67: =ROUNDUP(Q67/7.5,0) -> 1 | S67: =Q67/1690 -> 0.0035502959
A68: 46 | B68: Vestland | C68: 1832 | D68: Hemnes | E68: 869.1 | F68: 175 | G68: 1430 | H68: 4485 | I68: 0.61 | J68: 313 | K68: 194 | L68: 143 | O68: =IF(N68>0,ROUND((N68-E68)/E68*100,1),"") | P68: =ROUND((E68*Tidbruk!$J$1)+(G68*Tidbruk!$J$2),0) -> 1716 | Q68: =ROUNDUP(P68/60,0) -> 29 | R68: =ROUNDUP(Q68/7.5,0) -> 4 | S68: =Q68/1690 -> 0.017159763
A69: 40 | B69: Telemark | C69: 1833 | D69: Rana | E69: 1813.92 | F69: 46 | G69: 4203 | H69: 25927 | I69: 0.43 | J69: 339 | K69: 70 | L69: 249 | O69: =IF(N69>0,ROUND((N69-E69)/E69*100,1),"") | P69: =ROUND((E69*Tidbruk!$J$1)+(G69*Tidbruk!$J$2),0) -> 4375 | Q69: =ROUNDUP(P69/60,0) -> 73 | R69: =ROUNDUP(Q69/7.5,0) -> 10 | S69: =Q69/1690 -> 0.043195266
A70: 50 | B70: Trøndelag | C70: 1834 | D70: Lurøy | E70: 197.01 | F70: 333 | G70: 258 | H70: 1948 | I70: 0.76 | J70: 290 | K70: 101 | L70: 213 | O70: =IF(N70>0,ROUND((N70-E70)/E70*100,1),"") | P70: =ROUND((E70*Tidbruk!$J$1)+(G70*Tidbruk!$J$2),0) -> 346 | Q70: =ROUNDUP(P70/60,0) -> 6 | R70: =ROUNDUP(Q70/7.5,0) -> 1 | S70: =Q70/1690 -> 0.0035502959
A71: 46 | B71: Vestland | C71: 1835 | D71: Træna | E71: 11.12 | F71: 356 | G71: 16 | H71: 463 | I71: 0.7 | J71: 297 | K71: 24 | L71: 316 | O71: =IF(N71>0,ROUND((N71-E71)/E71*100,1),"") | P71: =ROUND((E71*Tidbruk!$J$1)+(G71*Tidbruk!$J$2),0) -> 20 | Q71: =ROUNDUP(P71/60,0) -> 1 | R71: =ROUNDUP(Q71/7.5,0) -> 1 | S71: =Q71/1690 -> 0.00059171598
A72: 50 | B72: Trøndelag | C72: 1836 | D72: Rødøy | E72: 232.38 | F72: 316 | G72: 686 | H72: 1160 | I72: 0.34 | J72: 348 | K72: 200 | L72: 141 | O72: =IF(N72>0,ROUND((N72-E72)/E72*100,1),"") | P72: =ROUND((E72*Tidbruk!$J$1)+(G72*Tidbruk!$J$2),0) -> 657 | Q72: =ROUNDUP(P72/60,0) -> 11 | R72: =ROUNDUP(Q72/7.5,0) -> 2 | S72: =Q72/1690 -> 0.0065088757
... A312: 18 | B312: Nordland | C312: 5054 | D312: Indre Fosen | E312: 1648.98 | F312: 57 | G312: 1030 | H312: 10042 | I312: 1.6 | J312: 163 | K312: 164 | L312: 157 | O312: =IF(N312>0,ROUND((N312-E312)/E312*100,1),"") | P312: =ROUND((E312*Tidbruk!$J$1)+(G312*Tidbruk!$J$2),0) -> 2160 | Q312: =ROUNDUP(P312/60,0) -> 36 | R312: =ROUNDUP(Q312/7.5,0) -> 5 | S312: =Q312/1690 -> 0.021301775
A313: 50 | B313: Trøndelag | C313: 5055 | D313: Heim | E313: 1264.49 | F313: 95 | G313: 980 | H313: 6134 | I313: 1.29 | J313: 205 | K313: 206 | L313: 138 | M313: 38 | N313: 231 | O313: =IF(N313>0,ROUND((N313-E313)/E313*100,1),"") -> -81.7 | P313: =ROUND((E313*Tidbruk!$J$1)+(G313*Tidbruk!$J$2),0) -> 1780 | Q313: =ROUNDUP(P313/60,0) -> 30 | R313: =ROUNDUP(Q313/7.5,0) -> 4 | S313: =Q313/1690 -> 0.017751479
A314: 46 | B314: Vestland | C314: 5056 | D314: Hitra | E314: 833.69 | F314: 183 | G314: 715 | H314: 5414 | I314: 1.17 | J314: 222 | K314: 154 | L314: 165 | O314: =IF(N314>0,ROUND((N314-E314)/E314*100,1),"") | P314: =ROUND((E314*Tidbruk!$J$1)+(G314*Tidbruk!$J$2),0) -> 1219 | Q314: =ROUNDUP(P314/60,0) -> 21 | R314: =ROUNDUP(Q314/7.5,0) -> 3 | S314: =Q314/1690 -> 0.012426036
...

Sheet Tidbruk
A1: R_KART | B1: OBJTYPE | C1: MIN | D1: LENGTH | E1: KM | F1: MIN/KM | G1: MIN/KM2 | H1: kortnavn | I1: Gjennomsnitt minutt per km lenke | J1: =AVERAGE(F:F) -> 0.90347467
A2: 32-5-518-227-10 | B2: Kartblad | C2: 18 | D2: 14909.18 | E2: =D2/1000 -> 14.90918 | F2: =C2/E2 -> 1.2073098 | G2: =C2/7.68 -> 2.34375 | H2: hvajen | I2: Grunnpakke landareal minutt per km2 | J2: =5/7.68 -> 0.65104167
A3: 32-5-519-227-00 | B3: Kartblad | C3: 17 | D3: 19009.686 | E3: =D3/1000 -> 19.009686 | F3: =C3/E3 -> 0.89428096 | G3: =C3/7.68 -> 2.2135417 | H3: hvajen
A4: 32-5-520-227-00 | B4: Kartblad | C4: 19 | D4: 14666.289 | E4: =D4/1000 -> 14.666289 | F4: =C4/E4 -> 1.2954879 | G4: =C4/7.68 -> 2.4739583 | H4: hvajen
A5: 32-5-520-227-10 | B5: Kartblad | C5: 11 | D5: 23209.329 | E5: =D5/1000 -> 23.209329 | F5: =C5/E5 -> 0.47394735 | G5: =C5/7.68 -> 1.4322917 | H5: hvajen
A6: 32-5-521-227-00 | B6: Kartblad | C6: 4 | D6: 17531.781 | E6: =D6/1000 -> 17.531781 | F6: =C6/E6 -> 0.22815708 | G6: =C6/7.68 -> 0.52083333 | H6: hvajen
A7: 32-5-521-227-10 | B7: Kartblad | C7: 2 | D7: 6674.1018 | E7: =D7/1000 -> 6.6741018 | F7: =C7/E7 -> 0.29966579 | G7: =C7/7.68 -> 0.26041667 | H7: hvajen
A8: 32-5-519-227-11 | B8: Kartblad | C8: 8 | D8: 14996.556 | E8: =D8/1000 -> 14.996556 | F8: =C8/E8 -> 0.5334558 | G8: =C8/7.68 -> 1.0416667 | H8: hvajen
A9: 32-5-519-228-10 | B9: Kartblad | C9: 24 | D9: 20516.809 | E9: =D9/1000 -> 20.516809 | F9: =C9/E9 -> 1.1697725 | G9: =C9/7.68 -> 3.125 | H9: hvajen
A10: 32-5-519-229-10 | B10: Kartblad | C10: 24 | D10: 17846.36 | E10: =D10/1000 -> 17.84636 | F10: =C10/E10 -> 1.344812 | G10: =C10/7.68 -> 3.125 | H10: hvajen
A11: 32-5-519-229-11 | B11: Kartblad | C11: 22 | D11: 23369.918 | E11: =D11/1000 -> 23.369918 | F11: =C11/E11 -> 0.94138116 | G11: =C11/7.68 -> 2.8645833 | H11: hvajen
A12: 32-5-519-230-10 | B12: Kartblad | C12: 19 | D12: 19486.987 | E12: =D12/1000 -> 19.486987 | F12: =C12/E12 -> 0.97500963 | G12: =C12/7.68 -> 2.4739583 | H12: hvajen
A13: 32-5-519-231-11 | B13: Kartblad | C13: 20 | D13: 9009.0549 | E13: =D13/1000 -> 9.0090549 | F13: =C13/E13 -> 2.2199887 | G13: =C13/7.68 -> 2.6041667 | H13: hvajen
A14: 32-5-519-232-11 | B14: Kartblad | C14: 25 | D14: 7260.2321 | E14: =D14/1000 -> 7.2602321 | F14: =C14/E14 -> 3.4434161 | G14: =C14/7.68 -> 3.2552083 | H14: hvajen
... A48: 32-5-518-229-10 | B48: Kartblad | C48: 15 | D48: 8826.4773 | E48: =D48/1000 -> 8.8264773 | F48: =C48/E48 -> 1.6994322 | G48: =C48/7.68 -> 1.953125 | H48: hvajen
A49: 32-5-529-143-01 | B49: Kartblad | C49: 5 | D49: 8814.0565 | E49: =D49/1000 -> 8.8140565 | F49: 0.567 | G49: =C49/7.68 -> 0.65104167 | H49: hoiani
A50: 32-5-528-143-11 | B50: Kartblad | C50: 5 | D50: 16203.19 | E50: =D50/1000 -> 16.20319 | F50: 0.309 | G50: =C50/7.68 -> 0.65104167 | H50: hoiani
A51: 32-5-528-143-01 | B51: Kartblad | C51: 8 | D51: 16320.169 | E51: =D51/1000 -> 16.320169 | F51: 0.49 | G51: =C51/7.68 -> 1.0416667 | H51: hoiani
A52: 32-5-527-143-11 | B52: Kartblad | C52: 20 | D52: 15666.042 | E52: =D52/1000 -> 15.666042 | F52: 1.277 | G52: =C52/7.68 -> 2.6041667 | H52: hoiani
A53: 32-5-527-143-01 | B53: Kartblad | C53: 15 | D53: 13412.368 | E53: =D53/1000 -> 13.412368 | F53: 1.118 | G53: =C53/7.68 -> 1.953125 | H53: hoiani
A54: 32-5-526-143-11 | B54: Kartblad | C54: 20 | D54: 13750.832 | E54: =D54/1000 -> 13.750832 | F54: 1.454 | G54: =C54/7.68 -> 2.6041667 | H54: hoiani
A55: 32-5-526-143-01 | B55: Kartblad | C55: 10 | D55: 10017.841 | E55: =D55/1000 -> 10.017841 | F55: 0.998 | G55: =C55/7.68 -> 1.3020833 | H55: hoiani
A56: 32-5-526-141-00 | B56: Kartblad | C56: 20 | D56: 12065.182 | E56: =D56/1000 -> 12.065182 | F56: 1.658 | G56: =C56/7.68 -> 2.6041667 | H56: hoiani
A57: 32-5-526-140-11 | B57: Kartblad | C57: 8 | D57: 11733.556 | E57: =D57/1000 -> 11.733556 | F57: 0.682 | G57: =C57/7.68 -> 1.0416667 | H57: hoiani
A58: 32-5-525-143-11 | B58: Kartblad | C58: 5 | D58: 10980.744 | E58: =D58/1000 -> 10.980744 | F58: 0.455 | G58: =C58/7.68 -> 0.65104167 | H58: hoiani
A59: 32-5-525-141-10 | B59: Kartblad | C59: 23 | D59: 23112.764 | E59: =D59/1000 -> 23.112764 | F59: 0.995 | G59: =C59/7.68 -> 2.9947917 | H59: hoiani

Sheet pivot
C3: Verdier
A4: fylkesnr | B4: fylkesnavn | C4: Summer av Dagsverk | D4: Summer av Årsverk
A5: 3 | B5: Oslo | C5: 5 | D5: 0.018343195
A6: 11 | B6: Rogaland | C6: 54 | D6: 0.19112426
A7: 15 | B7: Møre og Romsdal | C7: 66 | D7: 0.2408284
A8: 18 | B8: Nordland | C8: 120 | D8: 0.43668639
A9: 31 | B9: Østfold | C9: 28 | D9: 0.098224852
A10: 32 | B10: Akershus | C10: 45 | D10: 0.16153846
A11: 33 | B11: Buskerud | C11: 87 | D11: 0.33846154
A12: 34 | B12: Innlandet | C12: 238 | D12: 0.96331361
A13: 39 | B13: Vestfold | C13: 18 | D13: 0.069230769
A14: 40 | B14: Telemark | C14: 69 | D14: 0.27159763
A15: 42 | B15: Agder | C15: 86 | D15: 0.3443787
A16: 46 | B16: Vestland | C16: 147 | D16: 0.5591716
... A19: 56 | B19: Finnmark | C19: 121 | D19: 0.50236686
A20: Totalsum | C20: 1339 | D20: 5.1899408
